<?xml version="1.0" encoding="utf-8"?>
<!-- This URDF was automatically created by SolidWorks to URDF Exporter! Originally created by Stephen Brawner (brawner@gmail.com) 
     Commit Version: 1.6.0-4-g7f85cfe  Build Version: 1.6.7995.38578
     For more information, please see http://wiki.ros.org/sw_urdf_exporter -->
<robot
  name="left_leg">
  
  <link
    name="knee">
    <inertial>
      <origin
        xyz="0.0083741600267864 -1.38260606949159E-05 -0.140326741872988"
        rpy="0 0 0" />
      <mass
        value="1.9" />
      <inertia
        ixx="0.0110280658461993"
        ixy="1.81936202585807E-05"
        ixz="-0.000324492332926834"
        iyy="0.0112829957777815"
        iyz="8.89496046204543E-05"
        izz="0.000857506229386697" />
    </inertial>
    <visual>
      <origin
        xyz="0 0 0"
        rpy="0 0 0" />
      <geometry>
        <mesh
          filename="../meshes/l_knee.obj" />
      </geometry>
      <material
        name="">
        <color
          rgba="1 1 1 1" />
      </material>
    </visual>
    <!-- <collision>
      <origin
        xyz="0 0 0"
        rpy="0 0 0" />
      <geometry>
        <mesh
          filename="../meshes/l_knee.obj" />
      </geometry>
    </collision> -->
  </link>

  <link
    name="foot_pitch">
    <inertial>
      <origin
        xyz="-1.81202114396539E-07 1.81203019034015E-07 2.55351295663786E-15"
        rpy="0 0 0" />
      <mass
        value="0.042517" />
      <inertia
        ixx="5.13627197456046E-07"
        ixy="-2.23455328690084E-16"
        ixz="-2.99517054441959E-11"
        iyy="5.13627197456051E-07"
        iyz="-2.9487151330203E-11"
        izz="9.09837232073045E-07" />
    </inertial>
    <visual>
      <origin
        xyz="0 0 0"
        rpy="0 0 0" />
      <geometry>
        <mesh
          filename="../meshes/l_foot_pitch.obj" />
      </geometry>
      <material
        name="">
        <color
          rgba="1 1 1 1" />
      </material>
    </visual>
    <!-- <collision>
      <origin
        xyz="0 0 0"
        rpy="0 0 0" />
      <geometry>
        <mesh
          filename="../meshes/l_foot_pitch.obj" />
      </geometry>
    </collision> -->
  </link>
  <joint
    name="foot_pitch"
    type="continuous">
    <origin
      xyz="0 0 -0.346000000000004"
      rpy="0 0 0" />
    <parent
      link="knee" />
    <child
      link="foot_pitch" />
    <axis
      xyz="0 1 0" />
  </joint>
  
  <link
    name="foot_roll">
    <inertial>
      <origin
        xyz="0.00986618796288023 -8.14594069974139E-06 -0.0323276518433993"
        rpy="0 0 0" />
      <mass
        value="0.59706" />
      <inertia
        ixx="0.000129574142247561"
        ixy="1.87464188807015E-08"
        ixz="3.66139740707971E-06"
        iyy="0.00031519475110699"
        iyz="3.6373667328501E-09"
        izz="0.000418024913490438" />
    </inertial>
    <visual>
      <origin
        xyz="0 0 0"
        rpy="0 0 0" />
      <geometry>
        <mesh
          filename="../meshes/l_foot_roll.obj" />
      </geometry>
      <material
        name="">
        <color
          rgba="1 1 1 1" />
      </material>
    </visual>
  </link>
  <frame link="foot_roll" name="l_foot_socket_frame" xyz="-0.056027 0.0255 0.015" />
  <frame link="foot_roll" name="r_foot_socket_frame" xyz="-0.056027 -0.0255 0.015" />
  <joint
    name="foot_roll"
    type="continuous">
    <origin
      xyz="0 0 0"
      rpy="0 0 0" />
    <parent
      link="foot_pitch" />
    <child
      link="foot_roll" />
    <axis
      xyz="1 0 0" />
  </joint>
  <link
    name="l_bar">
    <inertial>
      <origin
        xyz="-0.0172816853676534 0.00661593706645544 -2.76944701804727E-06"
        rpy="0 0 0" />
      <mass
        value="0.041379" />
      <inertia
        ixx="3.02750710314275E-06"
        ixy="-1.66046577410115E-06"
        ixz="-1.20318411485415E-09"
        iyy="1.63403804389531E-05"
        iyz="-1.6175299289979E-10"
        izz="1.40552885852523E-05" />
    </inertial>
    <visual>
      <origin
        xyz="0 0 0"
        rpy="0 0 0" />
      <geometry>
        <mesh
          filename="../meshes/l_l_bar.obj" />
      </geometry>
      <material
        name="">
        <color
          rgba="0.898039215686275 0.917647058823529 0.929411764705882 1" />
      </material>
    </visual>
    <!-- <collision>
      <origin
        xyz="0 0 0"
        rpy="0 0 0" />
      <geometry>
        <mesh
          filename="../meshes/l_l_bar.obj" />
      </geometry>
    </collision> -->
  </link>
  <frame link="l_bar" name="l_bar_frame" xyz="0 -0.0085 0" /> <!-- add frame -->
  <joint
    name="l_bar"
    type="continuous">
    <origin
      xyz="0 0.0260000000000038 -0.09"
      rpy="0 0 0" />
    <parent
      link="knee" />
    <child
      link="l_bar" />
    <axis
      xyz="0 1 0" />
  </joint>
  <transmission type="SimpleTransmission">
    <joint name="l_bar" />
    <actuator name="l_bar_motor">
      <drake:gear_ratio value="10.0" />
      <drake:rotor_inertia value="0.0001002" />
    </actuator>
  </transmission>
  
  <link
    name="l_tendon">
    <inertial>
      <origin
        xyz="0.000909568327568541 -0.00107382534052314 -0.116411596117355"
        rpy="0 0 0" />
      <mass
        value="0.0723259128251804" />
      <inertia
        ixx="0.00040704088500347"
        ixy="1.27056915128903E-09"
        ixz="3.16090323841034E-06"
        iyy="0.000405860828607296"
        iyz="-1.63249540748846E-07"
        izz="2.48972857907671E-06" />
    </inertial>
    <visual>
      <origin
        xyz="0 0 0"
        rpy="0 0 0" />
      <geometry>
        <mesh
          filename="../meshes/l_l_tendon.obj" />
      </geometry>
      <material
        name="">
        <color
          rgba="0.898039215686275 0.917647058823529 0.929411764705882 1" />
      </material>
    </visual>
    <!-- <collision>
      <origin
        xyz="0 0 0"
        rpy="0 0 0" />
      <geometry>
        <mesh
          filename="../meshes/l_l_tendon.obj" />
      </geometry>
    </collision> -->
  </link>
  <drake:joint name="l_tendon" type="universal">
    <origin xyz="-0.056027 -0.0085 0.015" rpy="0 0 0" />
    <parent link="l_bar" />
    <child link="l_tendon" />
  </drake:joint>
  <frame link="l_tendon" name="l_tendon_socket_frame" xyz="0 0 -0.256" />
  <!-- <joint
    name="l_l_tendon"
    type="continuous">
    <origin
      xyz="-0.0579999994738184 0 0"
      rpy="0 0 0" />
    <parent
      link="l_l_bar" />
    <child
      link="l_l_tendon" />
    <axis
      xyz="0 1 0" />
  </joint> -->
  
  <link
    name="r_bar">
    <inertial>
      <origin
        xyz="-0.0172816853849475 -0.00661593706803836 -2.64615120038059E-06"
        rpy="0 0 0" />
      <mass
        value="0.041379" />
      <inertia
        ixx="3.02750743240102E-06"
        ixy="1.6604657435466E-06"
        ixz="-2.25261355073722E-09"
        iyy="1.63403804403762E-05"
        iyz="3.58590401955966E-10"
        izz="1.40552882575403E-05" />
    </inertial>
    <visual>
      <origin
        xyz="0 0 0"
        rpy="0 0 0" />
      <geometry>
        <mesh
          filename="../meshes/l_r_bar.obj" />
      </geometry>
      <material
        name="">
        <color
          rgba="0.898039215686275 0.917647058823529 0.929411764705882 1" />
      </material>
    </visual>
    <!-- <collision>
      <origin
        xyz="0 0 0"
        rpy="0 0 0" />
      <geometry>
        <mesh
          filename="../meshes/l_r_bar.obj" />
      </geometry>
    </collision> -->
  </link>
  <frame link="r_bar" name="r_bar_frame" xyz="0 0.0085 0" />

  <joint
    name="r_bar"
    type="continuous">
    <origin
      xyz="0 -0.0259999999999997 -0.153"
      rpy="0 0 0" />
    <parent
      link="knee" />
    <child
      link="r_bar" />
    <axis
      xyz="0 1 0" />
  </joint>
  <transmission type="SimpleTransmission">
    <joint name="r_bar" />
    <actuator name="r_bar_motor">
      <drake:gear_ratio value="10.0" />
      <drake:rotor_inertia value="0.0001002" />
    </actuator>
  </transmission>
  
  <link
    name="r_tendon">
    <inertial>
      <origin
        xyz="0.000886522110566654 0.00109368372663839 -0.0855352996218761"
        rpy="0 0 0" />
      <mass
        value="0.10643" />
      <inertia
        ixx="0.000181298310457033"
        ixy="-1.2618085713137E-09"
        ixz="1.85864592856586E-06"
        iyy="0.000180444607519788"
        iyz="1.22245058012766E-07"
        izz="1.97355040670682E-06" />
    </inertial>
    <visual>
      <origin
        xyz="0 0 0"
        rpy="0 0 0" />
      <geometry>
        <mesh
          filename="../meshes/l_r_tendon.obj" />
      </geometry>
      <material
        name="">
        <color
          rgba="0.898039215686275 0.917647058823529 0.929411764705882 1" />
      </material>
    </visual>
    <!-- <collision>
      <origin
        xyz="0 0 0"
        rpy="0 0 0" />
      <geometry>
        <mesh
          filename="../meshes/l_r_tendon.obj" />
      </geometry>
    </collision> -->
  </link>
  <drake:joint name="r_tendon" type="universal">
    <origin xyz="-0.056027 0.0085 0.015" rpy="0 0 0" />
    <parent link="r_bar" />
    <child link="r_tendon" />
  </drake:joint>
  <frame link="r_tendon" name="r_tendon_socket_frame" xyz="0 0 -0.193" />
  <!-- <joint
    name="r_tendon"
    type="continuous">
    <origin
      xyz="-0.0579999990742142 0 -1.03629629222279E-05"
      rpy="0 0 0" />
    <parent
      link="r_bar" />
    <child
      link="r_tendon" />
    <axis
      xyz="0 1 0" />
  </joint> -->
  
  <!-- add drake linear_bushing_rpy -->
  <drake:linear_bushing_rpy>
    <drake:bushing_frameC name="l_tendon_socket_frame" />
    <drake:bushing_frameA name="l_foot_socket_frame" />
    <!-- <drake:bushing_force_stiffness value="1000 1000 100000"/>
    <drake:bushing_force_damping value="10 10 200"/> -->
    <drake:bushing_force_stiffness value="0 0 0" />
    <drake:bushing_force_damping value="0 0 0" />
    <drake:bushing_torque_stiffness value="0 0 0" />
    <drake:bushing_torque_damping value="0 0 0" />
  </drake:linear_bushing_rpy>
  
  <drake:linear_bushing_rpy>
    <drake:bushing_frameA name="r_tendon_socket_frame" />
    <drake:bushing_frameC name="r_foot_socket_frame" />
    <!-- <drake:bushing_force_stiffness value="1000 1000 100000"/>
    <drake:bushing_force_damping value="10 10 200"/> -->
    <drake:bushing_force_stiffness value="0 0 0" />
    <drake:bushing_force_damping value="0 0 0" />
    <drake:bushing_torque_stiffness value="0 0 0" />
    <drake:bushing_torque_damping value="0 0 0" />
  </drake:linear_bushing_rpy>
</robot>